Workbook
Name _Hlk171681997: Rates!#REF!

Sheet Inception of Cover Rater
A1: INSURED
A2: INSURED ADDRESS | F2: BUILDER'S RISK - NOT COVERED
A3: STATE - LOCATION OF FARM | B3: AR
A4: COUNTY - LOCATION OF FARM
A5: PROPOSED EFFECTIVE DATE
A6: PROPOSED EXPIRY DATE
A8: Coverage No: | B8: Coverage Type | C8: Item Description | D8: Location # | E8: EXPIRING RISK LIMIT | F8: Risk Limit (Required) | G8: Year of Construction (Cov A & G) Year of Equipment (Cov F) | H8: Age of Roof | I8: Type of Roof | J8: Coverage Basis | K8: Cause of Loss | L8: Rate | M8: Premium | N8: Deductibles | O8: W/H Deductible
A9: Coverage A | B9: Dwelling | C9: #1 | F9: =E9*103% | N9: 2500
C10: #2 | F10: =E10*103% | N10: 2500
C11: #3 | F11: =E11*103% | N11: 2500
C12: #4 | F12: =E12*103% | N12: 2500
C13: #5 | F13: =E13*103% | N13: 2500
C14: #6 | F14: =E14*103% | N14: 2500
C15: Coverage A Total | F15: =SUM(F9:F14) | L15: =Rates!B1 | M15: =F15*L15
A16: Coverage B | B16: Private Structures | C16: #1 | F16: =E16*103% | N16: 2500
C17: #2 | F17: =E17*103% | N17: 2500
C18: #3 | F18: =E18*103% | N18: 2500
C19: #4 | F19: =E19*103% | N19: 2500
C20: #5 | F20: =E20*103% | N20: 2500
C21: #6 | F21: =E21*103% | N21: 2500
C22: Coverage B Total | F22: =SUM(F16:F21) | L22: =Rates!B2 | M22: =F22*L22
A23: Coverage C | B23: Personal Property - All | C23: #1 | F23: =E23 | N23: 2500
C24: #2 | F24: =E24 | N24: 2500
C25: #3 | F25: =E25 | N25: 2500
C26: #4 | F26: =E26 | N26: 2500
C27: #5 | F27: =E27 | N27: 2500
C28: #6 | F28: =E28 | N28: 2500
C29: Coverage C Total | F29: =SUM(F23:F27) | L29: 0.0045 | M29: =F29*L29
B30: Personal Property - Scheduled Jewelry | C30: #1 | F30: =E30 | N30: Nil
C31: #2 | F31: =E31 | N31: Nil
C32: #3 | F32: =E32 | N32: Nil
C33: Coverage C Total (Scheduled Jewelry ONLY) | F33: =SUM(F30:F32) | L33: 0.013 | M33: =F33*L33
A34: Coverage D | B34: Loss of Use (Additional Living Expenses) | C34: #1 | F34: =E34 | N34: Nil
C35: #2 | F35: =E35 | N35: Nil
C36: #3 | F36: =E36 | N36: Nil
C37: #4 | F37: =E37 | N37: Nil
C38: #5 | F38: =E38 | N38: Nil
C39: #6 | F39: =E39 | N39: Nil
C40: Coverage D Total | F40: =SUM(F34:F39) | L40: =Rates!B4 | M40: =F40*L40
A41: Coverage E | B41: Blanket Farm Personal Property | C41: MISC SMALL TOOLS, EQUIP, SUPPLIES | F41: 0 | L41: =Rates!B5 | M41: =F41*L41 | N41: 1000
...

Sheet MTA Rater (Amended)
A1: INSURED | B1: ='Inception of Cover Rater'!B1
A2: INSURED ADDRESS | B2: ='Inception of Cover Rater'!B2 | E2: BUILDER'S RISK - NOT COVERED
A3: STATE - LOCATION OF FARM | B3: ='Inception of Cover Rater'!B3
A4: COUNTY - LOCATION OF FARM | B4: ='Inception of Cover Rater'!B4
A5: PROPOSED EFFECTIVE DATE | B5: ='Inception of Cover Rater'!B5
A6: PROPOSED EXPIRY DATE | B6: ='Inception of Cover Rater'!B6
A8: Coverage No: | B8: Coverage Type | C8: Item Description | D8: Location # | E8: Risk Limit (Required) | F8: Year of Construction (Cov A & G) Year of Equipment (Cov F) | G8: Age of Roof | H8: Type of Roof | I8: Coverage Basis | J8: Cause of Loss | K8: Rate | L8: Premium | M8: Deductibles | N8: W/H Deductible
A9: Coverage A | B9: Dwelling | C9: #1 | E9: 450000 | F9: 2024 | G9: 2 | H9: Shingles | I9: Replacement Cost | J9: Basic | M9: 2500
C10: #2 | E10: 0 | M10: 2500
C11: #3 | E11: 0 | M11: 2500
C12: #4 | E12: 0 | M12: 2500
C13: #5 | E13: 0 | M13: 2500
C14: #6 | E14: 0 | M14: 2500
C15: Coverage A Total | E15: =SUM(E9:E14) | K15: 0.0045 | L15: =E15*K15
A16: Coverage B | B16: Private Structures | C16: #1 | E16: 50000 | M16: 2500
C17: #2 | E17: 0 | M17: 2500
C18: #3 | E18: 0 | M18: 2500
C19: #4 | E19: 0 | M19: 2500
C20: #5 | E20: 0 | M20: 2500
C21: #6 | E21: 0 | M21: 2500
C22: Coverage B Total | E22: =SUM(E16:E21) | K22: 0.0045 | L22: =E22*K22
A23: Coverage C | B23: Personal Property - All | C23: #1 | E23: 30000 | M23: 2500
C24: #2 | E24: 0 | M24: 2500
C25: #3 | E25: 0 | M25: 2500
C26: #4 | E26: 0 | M26: 2500
C27: #5 | E27: 0 | M27: 2500
C28: #6 | E28: 0 | M28: 2500
C29: Coverage C Total | E29: =SUM(E23:E27) | K29: 0.0045 | L29: =E29*K29
B30: Personal Property - Scheduled Jewelry | C30: #1 | E30: 10000 | M30: Nil
C31: #2 | E31: 0 | M31: Nil
C32: #3 | E32: 0 | M32: Nil
C33: Coverage C Total (Scheduled Jewelry ONLY) | E33: =SUM(E30:E32) | K33: 0.013 | L33: =E33*K33
A34: Coverage D | B34: Loss of Use (Additional Living Expenses) | C34: #1 | E34: 3000 | M34: Nil
C35: #2 | E35: 0 | M35: Nil
C36: #3 | E36: 0 | M36: Nil
C37: #4 | E37: 0 | M37: Nil
C38: #5 | E38: 0 | M38: Nil
C39: #6 | E39: 0 | M39: Nil
C40: Coverage D Total | E40: =SUM(E34:E39) | K40: 0.0045 | L40: =E40*K40
A41: Coverage E | B41: Blanket Farm Personal Property | C41: MISC SMALL TOOLS, EQUIP, SUPPLIES | E41: 35000 | K41: 0.0045 | L41: =E41*K41 | M41: 1000
...

Sheet Rates
A1: Coverage A – Dwelling | B1: 0.004
A2: Coverage B – Private Structures | B2: 0.0045
A3: Coverage C – Personal Property | B3: 0.0055
A4: Coverage D – Loss of Use | B4: 0.0046
A5: Coverage E - Blanket Farm Perosnal Property | B5: 0.004
A6: Coverage F - Scheduled Farm Personal Property Coverage | B6: 0.004
A7: Coverage G – Farm Outbuildings and Structures | B7: Nil | C7: Zone 1 | D7: Zone 2 | E7: Zone 3 | F7: Zone 4
A8: Breeder Complex | B8: 0 | C8: 0.006 | D8: 0.007 | E8: 0.0055 | F8: 0.007
A9: Standard Breeder | B9: 0 | C9: 0.0047 | D9: 0.0047 | E9: 0.0054 | F9: 0.0061
A10: Primary Breeder | B10: 0 | C10: 0.0044 | D10: 0.0044 | E10: 0.0044 | F10: 0.0055
A11: Standard Broilers | B11: 0 | C11: 0.0048 | D11: 0.005 | E11: 0.005 | F11: 0.0064
A12: Mega-house Broilers | B12: 0 | C12: 0.005 | D12: 0.005 | E12: 0.0052 | F12: 0.0057
A13: Coverage H- Farm Personal Liability | B13: 500 | C13: per policy | D13: Limit USD 1,000,000, USD 2,000,000 in the annual aggregate.
A14: Coverage I - Medical Payments to Others | B14: Included
A15: Coverage J - Farm Employers Liability | B15: 80 | C15: (Full-time Employee)
B16: 60 | C16: (Part-time Employee)
A17: Coverage K - Farm Employees Medical Payments | B17: Included
A18: Coverage L - Care, Custody and Control
A19: Coverage M - Loss of Farm Income (Business Interruption) | B19: 0.0045
A20: Section I - Additional Coverages | B20: 0.00015 | C20: Farm Equipment Breakdown Coverage
B21: 40 | C21: Identity Fraud Expense Coverage
A22: Section II - Additional Coverages | B22: 200 | C22: Farm Pollution Liability Coverage
A25: BUILDER'S RISK - NOT COVERED
A26: BUILDER'S RISK - COVERED (Course of Construction endorsement to be included with Policy)
A29: Coverage A - Type of Roof | B29: Metal | C29: Shingles | D29: Wood Shakes
A31: Private jewellery for wearing | B31: Maximum limit per policy USD 100,000
B32: Maximum limit per item USD10,000
B33: (Otherwise, prior submit to Underwriters)
A35: Rates: | B35: 0.013 | C35: Kept in safe in Private dwelling when not worn, no alarm
B36: 0.02 | C36: no safe, kept in Private dwelling when not worn, no alarm

Sheet States
A1: AL | B1: 0.06
A2: AR | B2: 0.04
A3: GA | B3: 0.04
A4: IA | B4: 0.0095
A5: KS | B5: 0.03
A6: KY | B6: 0.048
A7: MO | B7: 0.05
A8: MS | B8: 0.0725
A9: NE | B9: 0.03
A10: NM | B10: 0.05
A11: OK | B11: 0.06
A12: SC | B12: 0.06
... A15: VA | B15: 0.0225
A17: Coverage Basis | B17: Replacement Cost | C17: Actual Cash Value
A18: Cause of Loss | B18: Basic | C18: Broad | D18: Special

Sheet SystemInception
A1: CoverageA | B1: CoverageB | C1: CoverageC | D1: CoverageD | E1: CoverageE | F1: CoverageF | G1: CoverageG | H1: CoverageH | I1: CoverageI | J1: CoverageJ | K1: CoverageK | L1: CoverageL | M1: CoverageM | N1: FarmEquipmentBreakdownCoverage | O1: IdentityFraudExpenseCoverage | P1: FarmPollutionLiabilityCoverage | Q1: Annual_Amount | R1: Liability | S1: Property | T1: AdditionalSections | U1: RiskCodeN | V1: RiskCodeB3 | W1: RiskCodeUA | X1: RiskCodeUR | Y1: RiskCodeNAmount | Z1: RiskCodeB3Amount | AA1: RiskCodeUAAmount | AB1: RiskCodeURAmount | AC1: TerrDeclDate | AD1: ExcessDed | AE1: # of broiler houses
A2: ='Inception of Cover Rater'!M15 | B2: ='Inception of Cover Rater'!M22 | C2: ='Inception of Cover Rater'!M33 | D2: ='Inception of Cover Rater'!M40 | E2: ='Inception of Cover Rater'!M41 | F2: ='Inception of Cover Rater'!M62 | G2: ='Inception of Cover Rater'!M89 | H2: ='Inception of Cover Rater'!M90 | I2: ='Inception of Cover Rater'!M91 | J2: ='Inception of Cover Rater'!M92 | K2: ='Inception of Cover Rater'!M93 | L2: ='Inception of Cover Rater'!M94 | M2: ='Inception of Cover Rater'!M95 | N2: ='Inception of Cover Rater'!M96 | O2: ='Inception of Cover Rater'!M97 | P2: ='Inception of Cover Rater'!M98 | Q2: =SUM(A2:P2) | R2: ='Inception of Cover Rater'!B134 | S2: ='Inception of Cover Rater'!B135 | T2: ='Inception of Cover Rater'!B136 | U2: ='Inception of Cover Rater'!B141 | V2: ='Inception of Cover Rater'!B142 | W2: ='Inception of Cover Rater'!B143 | X2: ='Inception of Cover Rater'!B144 | Y2: ='Inception of Cover Rater'!F95 | Z2: ='Inception of Cover Rater'!F96 | AA2: ='Inception of Cover Rater'!F90 | AB2: ='Inception of Cover Rater'!F92 | AC2: ='Inception of Cover Rater'!J141 | AD2: ='Inception of Cover Rater'!N63 | AE2: 0

Sheet Tier 1 & 2
A1: Statecode | B1: Tier | C1: County
A2: AL | B2: 1 | C2: BALDWIN COUNTY
A3: AL | B3: 1 | C3: MOBILE COUNTY
A4: AL | B4: 2 | C4: CLARKE COUNTY
A5: AL | B5: 2 | C5: COVINGTON COUNTY
A6: AL | B6: 2 | C6: ESCAMBIA COUNTY
A7: AL | B7: 2 | C7: GENEVA COUNTY
A8: AL | B8: 2 | C8: MONROE COUNTY
A9: AL | B9: 2 | C9: WASHINGTON COUNTY
A10: CT | B10: 1 | C10: FAIRFIELD COUNTY
A11: CT | B11: 1 | C11: MIDDLESEX COUNTY
A12: CT | B12: 1 | C12: NEW HAVEN COUNTY
A13: CT | B13: 1 | C13: NEW LONDON COUNTY
... A324: VA | B324: 2 | C324: SUSSEX COUNTY

Sheet MTACoverage
A1: CoverageA | B1: CoverageB | C1: CoverageC | D1: CoverageD | E1: CoverageE | F1: CoverageF | G1: CoverageG | H1: CoverageH | I1: CoverageI | J1: CoverageJ | K1: CoverageK | L1: CoverageL | M1: CoverageM | N1: FarmEquipmentBreakdownCoverage | O1: IdentityFraudExpenseCoverage | P1: FarmPollutionLiabilityCoverage | Q1: Annual_Amount | R1: Liability | S1: Property | T1: AdditionalSections | U1: RiskCodeN | V1: RiskCodeB3 | W1: RiskCodeUA | X1: RiskCodeUR | Y1: RiskCodeNAmount | Z1: RiskCodeB3Amount | AA1: RiskCodeUAAmount | AB1: RiskCodeURAmount | AC1: TerrDeclDate | AD1: ExcessDed | AE1: # of broiler houses
A2: ='MTA Rater (Amended)'!L15 | B2: ='MTA Rater (Amended)'!L22 | C2: ='MTA Rater (Amended)'!L33 | D2: ='MTA Rater (Amended)'!L40 | E2: ='MTA Rater (Amended)'!L41 | F2: ='MTA Rater (Amended)'!L62 | G2: ='MTA Rater (Amended)'!L89 | H2: ='MTA Rater (Amended)'!L90 | I2: ='MTA Rater (Amended)'!L91 | J2: ='MTA Rater (Amended)'!L92 | K2: ='MTA Rater (Amended)'!L93 | L2: ='MTA Rater (Amended)'!L94 | M2: ='MTA Rater (Amended)'!L95 | N2: ='MTA Rater (Amended)'!L96 | O2: ='MTA Rater (Amended)'!L97 | P2: ='MTA Rater (Amended)'!L98 | Q2: =SUM(A2:P2) | R2: ='MTA Rater (Amended)'!B134 | S2: ='MTA Rater (Amended)'!B135 | T2: ='MTA Rater (Amended)'!B136 | U2: ='MTA Rater (Amended)'!B141 | V2: ='MTA Rater (Amended)'!B142 | W2: ='MTA Rater (Amended)'!B143 | X2: ='MTA Rater (Amended)'!B144 | Y2: ='MTA Rater (Amended)'!E95 | Z2: ='Inception of Cover Rater'!F96 | AA2: ='MTA Rater (Amended)'!E90 | AB2: ='MTA Rater (Amended)'!E92 | AC2: ='MTA Rater (Amended)'!I138 | AD2: ='MTA Rater (Amended)'!M63 | AE2: 6

Sheet Cole Quote Sheet
A10: FOR ALL YOUR INSURANCE & BOND NEEDS
A12: An Oakbridge Insurance partner
A14: ='Inception of Cover Rater'!$B$1
A17: Location 1: | B17: ='Inception of Cover Rater'!$B$2
A18: Acreage: | B18: ='Inception of Cover Rater'!$C$108
A20: Coverage | B20: Description | C20: Coverage Basis | D20: Cause of Loss | E20: Deductible | F20: W/H Deductible | G20: Proposed Sum Insured
A21: Farm Outbuilding and Structures (Coverage G) | B21: ='Inception of Cover Rater'!C63 | C21: ='Inception of Cover Rater'!J63 | D21: ='Inception of Cover Rater'!K63 | E21: ='Inception of Cover Rater'!N63 | F21: ='Inception of Cover Rater'!O63 | G21: ='Inception of Cover Rater'!F63
B22: ='Inception of Cover Rater'!C64 | C22: ='Inception of Cover Rater'!J64 | D22: ='Inception of Cover Rater'!K64 | E22: ='Inception of Cover Rater'!N64 | F22: ='Inception of Cover Rater'!O64 | G22: ='Inception of Cover Rater'!F64
B23: ='Inception of Cover Rater'!C65 | C23: ='Inception of Cover Rater'!J65 | D23: ='Inception of Cover Rater'!K65 | E23: ='Inception of Cover Rater'!N65 | F23: ='Inception of Cover Rater'!O65 | G23: ='Inception of Cover Rater'!F65
A25: Schedule Farm Personal Property (Coverage F) | B25: ='Inception of Cover Rater'!F42 | C25: ='Inception of Cover Rater'!J42 | D25: ='Inception of Cover Rater'!K42 | E25: ='Inception of Cover Rater'!N42 | F25: Nil | G25: ='Inception of Cover Rater'!F42
B26: ='Inception of Cover Rater'!F43 | C26: ='Inception of Cover Rater'!J43 | D26: ='Inception of Cover Rater'!K43 | E26: ='Inception of Cover Rater'!N43 | F26: Nil | G26: ='Inception of Cover Rater'!F43
B27: ='Inception of Cover Rater'!F44 | C27: ='Inception of Cover Rater'!J44 | D27: ='Inception of Cover Rater'!K44 | E27: ='Inception of Cover Rater'!N44 | F27: Nil | G27: ='Inception of Cover Rater'!F44
A29: Farm Equipment Breakdown Coverage | E29: Nil | F29: Nil | G29: ='Inception of Cover Rater'!F96
A31: Loss of Farm Income - Business Interruption (Coverage M) | E31: Nil | F31: Nil | G31: ='Inception of Cover Rater'!F95
A33: Farm Personal Liability | B33: $2,000,000 IN THE ANNUAL AGGREGATE | E33: Nil | F33: Nil | G33: ='Inception of Cover Rater'!F90
A35: Medical Payments to Others | E35: Nil | F35: Nil | G35: ='Inception of Cover Rater'!F91
A37: Farm Employers Liability | B37: $1,000,000 IN THE ANNUAL AGGREGATE | E37: Nil | F37: Nil | G37: ='Inception of Cover Rater'!F92
A39: Farm Employees Medical Payment | E39: Nil | F39: Nil | G39: ='Inception of Cover Rater'!F93
A41: Blanket Farm Personal Property (Coverage E) | B41: ='Inception of Cover Rater'!$C$41 | E41: ='Inception of Cover Rater'!$N$41 | F41: Nil | G41: ='Inception of Cover Rater'!$F$41
A43: Annual Premium | B43: ='Inception of Cover Rater'!$M$109
A45: **** QUOTE INCLUDES: | B45: BROAD PERILS WHICH COVER COLLAPSE FROM ICE/SHOW
B46: COSMETIC DAMAGE EXCLUSION TO ROOFS FROM WIND/HAIL

Sheet _Schema
A1: field | B1: cell | C1: type | D1: label | E1: direction | F1: group | G1: options | H1: default
A2: insured_b1 | B2: B1 | C2: text | D2: INSURED | E2: input | F2: Policy Info
A3: insured_address_b2 | B3: B2 | C3: text | D3: INSURED ADDRESS | E3: input | F3: Policy Info
A4: state_location_of_farm_b3 | B4: B3 | C4: text | D4: STATE - LOCATION OF FARM | E4: input | F4: Policy Info | H4: AR
A5: county_location_of_farm_b4 | B5: B4 | C5: text | D5: COUNTY - LOCATION OF FARM | E5: input | F5: Policy Info
A6: proposed_effective_date_b5 | B6: B5 | C6: text | D6: PROPOSED EFFECTIVE DATE | E6: input | F6: Policy Info
A7: proposed_expiry_date_b6 | B7: B6 | C7: text | D7: PROPOSED EXPIRY DATE | E7: input | F7: Policy Info
A8: f_1_location_d9 | B8: D9 | C8: dropdown | D8: #1 (Location #) | E8: input | F8: Coverage A-D | G8: Loc #1;Loc #2;Loc #3;Loc #4;Loc #5;Loc #6
A9: f_2_location_d10 | B9: D10 | C9: dropdown | D9: #2 (Location #) | E9: input | F9: Coverage A-D | G9: Loc #1;Loc #2;Loc #3;Loc #4;Loc #5;Loc #6
A10: f_3_location_d11 | B10: D11 | C10: dropdown | D10: #3 (Location #) | E10: input | F10: Coverage A-D | G10: Loc #1;Loc #2;Loc #3;Loc #4;Loc #5;Loc #6
A11: f_4_location_d12 | B11: D12 | C11: dropdown | D11: #4 (Location #) | E11: input | F11: Coverage A-D | G11: Loc #1;Loc #2;Loc #3;Loc #4;Loc #5;Loc #6
A12: f_5_location_d13 | B12: D13 | C12: dropdown | D12: #5 (Location #) | E12: input | F12: Coverage A-D | G12: Loc #1;Loc #2;Loc #3;Loc #4;Loc #5;Loc #6
A13: f_6_location_d14 | B13: D14 | C13: dropdown | D13: #6 (Location #) | E13: input | F13: Coverage A-D | G13: Loc #1;Loc #2;Loc #3;Loc #4;Loc #5;Loc #6
A14: f_1_location_d16 | B14: D16 | C14: dropdown | D14: #1 (Location #) | E14: input | F14: Coverage A-D | G14: Loc #1;Loc #2;Loc #3;Loc #4;Loc #5;Loc #6
A15: f_2_location_d17 | B15: D17 | C15: dropdown | D15: #2 (Location #) | E15: input | F15: Coverage A-D | G15: Loc #1;Loc #2;Loc #3;Loc #4;Loc #5;Loc #6
A16: f_3_location_d18 | B16: D18 | C16: dropdown | D16: #3 (Location #) | E16: input | F16: Coverage A-D | G16: Loc #1;Loc #2;Loc #3;Loc #4;Loc #5;Loc #6
A17: f_4_location_d19 | B17: D19 | C17: dropdown | D17: #4 (Location #) | E17: input | F17: Coverage A-D | G17: Loc #1;Loc #2;Loc #3;Loc #4;Loc #5;Loc #6
A18: f_5_location_d20 | B18: D20 | C18: dropdown | D18: #5 (Location #) | E18: input | F18: Coverage A-D | G18: Loc #1;Loc #2;Loc #3;Loc #4;Loc #5;Loc #6
A19: f_6_location_d21 | B19: D21 | C19: dropdown | D19: #6 (Location #) | E19: input | F19: Coverage A-D | G19: Loc #1;Loc #2;Loc #3;Loc #4;Loc #5;Loc #6
... A58: f_2_location_d64 | B58: D64 | C58: dropdown | D58: #2 (Location #) | E58: input | F58: Coverage G | G58: Loc #1;Loc #2;Loc #3;Loc #4;Loc #5;Loc #6
A59: f_2_risk_limit_e64 | B59: E64 | C59: number | D59: #2 (Risk Limit) | E59: input | F59: Coverage G | H59: 0
A60: f_3_location_d65 | B60: D65 | C60: dropdown | D60: #3 (Location #) | E60: input | F60: Coverage G | G60: Loc #1;Loc #2;Loc #3;Loc #4;Loc #5;Loc #6
A61: f_3_risk_limit_e65 | B61: E65 | C61: number | D61: #3 (Risk Limit) | E61: input | F61: Coverage G | H61: 0
A62: f_4_location_d66 | B62: D66 | C62: dropdown | D62: #4 (Location #) | E62: input | F62: Coverage G | G62: Loc #1;Loc #2;Loc #3;Loc #4;Loc #5;Loc #6
A63: f_4_risk_limit_e66 | B63: E66 | C63: number | D63: #4 (Risk Limit) | E63: input | F63: Coverage G | H63: 0
A64: f_5_location_d67 | B64: D67 | C64: dropdown | D64: #5 (Location #) | E64: input | F64: Coverage G | G64: Loc #1;Loc #2;Loc #3;Loc #4;Loc #5;Loc #6
A65: f_5_risk_limit_e67 | B65: E67 | C65: number | D65: #5 (Risk Limit) | E65: input | F65: Coverage G | H65: 0
A66: f_6_location_d68 | B66: D68 | C66: dropdown | D66: #6 (Location #) | E66: input | F66: Coverage G | G66: Loc #1;Loc #2;Loc #3;Loc #4;Loc #5;Loc #6
A67: f_6_risk_limit_e68 | B67: E68 | C67: number | D67: #6 (Risk Limit) | E67: input | F67: Coverage G | H67: 0
A68: f_7_location_d69 | B68: D69 | C68: dropdown | D68: #7 (Location #) | E68: input | F68: Coverage G | G68: Loc #1;Loc #2;Loc #3;Loc #4;Loc #5;Loc #6
A69: f_7_risk_limit_e69 | B69: E69 | C69: number | D69: #7 (Risk Limit) | E69: input | F69: Coverage G | H69: 0
A70: f_8_location_d70 | B70: D70 | C70: dropdown | D70: #8 (Location #) | E70: input | F70: Coverage G | G70: Loc #1;Loc #2;Loc #3;Loc #4;Loc #5;Loc #6
A71: f_8_risk_limit_e70 | B71: E70 | C71: number | D71: #8 (Risk Limit) | E71: input | F71: Coverage G | H71: 0
A72: f_9_location_d71 | B72: D71 | C72: dropdown | D72: #9 (Location #) | E72: input | F72: Coverage G | G72: Loc #1;Loc #2;Loc #3;Loc #4;Loc #5;Loc #6
A73: f_9_risk_limit_e71 | B73: E71 | C73: number | D73: #9 (Risk Limit) | E73: input | F73: Coverage G | H73: 0
A74: f_10_location_d72 | B74: D72 | C74: dropdown | D74: #10 (Location #) | E74: input | F74: Coverage G | G74: Loc #1;Loc #2;Loc #3;Loc #4;Loc #5;Loc #6
A75: f_10_risk_limit_e72 | B75: E72 | C75: number | D75: #10 (Risk Limit) | E75: input | F75: Coverage G | H75: 0
A76: f_11_location_d73 | B76: D73 | C76: dropdown | D76: #11 (Location #) | E76: input | F76: Coverage G | G76: Loc #1;Loc #2;Loc #3;Loc #4;Loc #5;Loc #6
A77: f_11_risk_limit_e73 | B77: E73 | C77: number | D77: #11 (Risk Limit) | E77: input | F77: Coverage G | H77: 0
A78: f_12_location_d74 | B78: D74 | C78: dropdown | D78: #12 (Location #) | E78: input | F78: Coverage G | G78: Loc #1;Loc #2;Loc #3;Loc #4;Loc #5;Loc #6
...
